Building DAG of jobs...
Creating conda environment envs/py.yml...
Downloading and installing remote packages.
CreateCondaEnvironmentException:
Could not create conda environment from /work/project/briefwp3/Adela/GA_CT/workflow/envs/py.yml:
Command:
mamba env create --quiet --file "/work/project/briefwp3/Adela/GA_CT/workflow/.snakemake/conda/6c07112a94dc2f9f200d9f4dc0aa77fa_.yaml" --prefix "/work/project/briefwp3/Adela/GA_CT/workflow/.snakemake/conda/6c07112a94dc2f9f200d9f4dc0aa77fa_"
Output:
error    libmamba Could not open lockfile '/usr/local/bioinfo/src/Miniconda/Miniconda3/pkgs/cache/cache.lock'
warning  libmamba Cache file "/usr/local/bioinfo/src/Miniconda/Miniconda3/pkgs/cache/47929eba.json" was modified by another program
error    libmamba Could not open lockfile '/usr/local/bioinfo/src/Miniconda/Miniconda3/pkgs/cache/cache.lock'
warning  libmamba Cache file "/usr/local/bioinfo/src/Miniconda/Miniconda3/pkgs/cache/3e39a7aa.json" was modified by another program
error    libmamba Could not open lockfile '/usr/local/bioinfo/src/Miniconda/Miniconda3/pkgs/cache/cache.lock'
warning  libmamba Cache file "/usr/local/bioinfo/src/Miniconda/Miniconda3/pkgs/cache/2ce54b42.json" was modified by another program
error    libmamba Could not open lockfile '/usr/local/bioinfo/src/Miniconda/Miniconda3/pkgs/cache/cache.lock'
warning  libmamba Cache file "/usr/local/bioinfo/src/Miniconda/Miniconda3/pkgs/cache/4ea078d6.json" was modified by another program

# >>>>>>>>>>>>>>>>>>>>>> ERROR REPORT <<<<<<<<<<<<<<<<<<<<<<

    Traceback (most recent call last):
      File "/usr/local/bioinfo/src/Miniconda/Miniconda3/lib/python3.10/site-packages/conda/exceptions.py", line 1132, in __call__
        return func(*args, **kwargs)
      File "/usr/local/bioinfo/src/Miniconda/Miniconda3/lib/python3.10/site-packages/conda_env/cli/main.py", line 78, in do_call
        exit_code = getattr(module, func_name)(args, parser)
      File "/usr/local/bioinfo/src/Miniconda/Miniconda3/lib/python3.10/site-packages/conda/notices/core.py", line 121, in wrapper
        return func(*args, **kwargs)
      File "/usr/local/bioinfo/src/Miniconda/Miniconda3/lib/python3.10/site-packages/conda_env/cli/main_create.py", line 152, in execute
        result[installer_type] = installer.install(prefix, pkg_specs, args, env)
      File "/usr/local/bioinfo/src/Miniconda/Miniconda3/lib/python3.10/site-packages/mamba/mamba_env.py", line 55, in mamba_install
        index = load_channels(pool, channel_urls, repos, prepend=False)
      File "/usr/local/bioinfo/src/Miniconda/Miniconda3/lib/python3.10/site-packages/mamba/utils.py", line 129, in load_channels
        index = get_index(
      File "/usr/local/bioinfo/src/Miniconda/Miniconda3/lib/python3.10/site-packages/mamba/utils.py", line 110, in get_index
        is_downloaded = dlist.download(api.MAMBA_DOWNLOAD_FAILFAST)
    RuntimeError: Multi-download failed. Reason: Transfer finalized, status: 404 [https://conda.anaconda.org/biopython/noarch/repodata.json] 2382 bytes

`$ /usr/local/bioinfo/src/Miniconda/Miniconda3/bin/mamba create --quiet --file /work/project/briefwp3/Adela/GA_CT/workflow/.snakemake/conda/6c07112a94dc2f9f200d9f4dc0aa77fa_.yaml --prefix /work/project/briefwp3/Adela/GA_CT/workflow/.snakemake/conda/6c07112a94dc2f9f200d9f4dc0aa77fa_`

  environment variables:
                 CIO_TEST=<not set>
  CONDA_AUTO_UPDATE_CONDA=false
               CONDA_ROOT=/usr/local/bioinfo/src/Miniconda/Miniconda3
           CURL_CA_BUNDLE=<not set>
         EAR_INSTALL_PATH=/opt/ear
          LD_LIBRARY_PATH=/tools/devel/python/Python-3.11.1/lib/
               LD_PRELOAD=<not set>
                  MANPATH=/tools/tools/modules/4.6.1/share/man::/opt/ear/man
               MODULEPATH=/tools/modulefiles/
                     PATH=/usr/local/bioinfo/src/Snakemake/snakemake-v8.3.1/snakemake-
                          v8.3.1_venv/bin:/usr/local/bioinfo/src/Miniconda/Miniconda3/bin/:/usr/
                          local/bioinfo/src/Snakemake/snakemake-v8.3.1/snakemake-
                          v8.3.1_venv/bin:/tools/bin:/tools/tools/modules/4.6.1/bin:/usr/lpp/mmf
                          s/bin/:/tools/perl5/modules/bin:/usr/local/bin:/usr/bin:/usr/local/sbi
                          n:/usr/sbin:/opt/ear/bin
       REQUESTS_CA_BUNDLE=<not set>
            SSL_CERT_FILE=<not set>

     active environment : None
       user config file : /home/apoublan/.condarc
 populated config files : /home/apoublan/.condarc
          conda version : 23.3.1
    conda-build version : not installed
         python version : 3.10.10.final.0
       virtual packages : __archspec=1=x86_64
                          __glibc=2.28=0
                          __linux=4.18.0=0
                          __unix=0=0
       base environment : /usr/local/bioinfo/src/Miniconda/Miniconda3  (read only)
      conda av data dir : /usr/local/bioinfo/src/Miniconda/Miniconda3/etc/conda
  conda av metadata url : None
           channel URLs : https://repo.anaconda.com/pkgs/main/linux-64
                          https://repo.anaconda.com/pkgs/main/noarch
                          https://repo.anaconda.com/pkgs/r/linux-64
                          https://repo.anaconda.com/pkgs/r/noarch
          package cache : /usr/local/bioinfo/src/Miniconda/Miniconda3/pkgs
                          /home/apoublan/.conda/pkgs
       envs directories : /home/apoublan/.conda/envs
                          /usr/local/bioinfo/src/Miniconda/Miniconda3/envs
               platform : linux-64
             user-agent : conda/23.3.1 requests/2.31.0 CPython/3.10.10 Linux/4.18.0-477.10.1.el8_8.x86_64 rhel/8.8 glibc/2.28
                UID:GID : 16884:1122
             netrc file : None
           offline mode : False


An unexpected error has occurred. Conda has prepared the above report.


